Workbook

Sheet Source Pass Summary
A1: Monstare Evidence Matrix - Source Location Pass v2
A2: Date | B2: 2026-08-13
A3: Scope | B3: Completed another source-location pass on remaining Priority A rows; after all A rows had a located source or access path, initiated Priority B pass through core theory + philosophy/QS rows.
A4: Priority A outcome | B4: All remaining Priority A rows now have a readable URL, restricted but legal access path, or authoritative landing/source path recorded.
A5: Priority B outcome | B5: Priority B started: core rows and Area 1/Area 2 early cluster updated where sources were found in this pass. Remaining B rows are left queued for the next pass.
A6: Halting principle | B6: Stopped after A completion plus a coherent B tranche, rather than forcing weak/unverified links into the matrix. Rows with landing-only/restricted access are clearly marked.
A7: Quality law | B7: Citation is still not evidence. Rows are source-located, not charted, until findings/effects/limits/disconfirmation are completed.
A8: Rows updated | B8: 77
A10: PATCH UPDATE v3
A11: Patch date | B11: 2026-08-13
A12: Additive additions | B12: 38 previously queued/missing rows source-located; 5 staleness columns added.
A13: Subtractions | B13: None. No evidence rows, existing source URLs, comments, or formulas intentionally removed.
A14: Quality law | B14: Source-located does not mean charted; findings/effects/limits/disconfirmation still require charting.

Sheet Guide & Legend
A1: MONSTARE EVIDENCE MATRIX
A2: Rev 5 schema | Stage 3 charting instrument | Prepared for Dallas by Pip, with Locus/Council logic | 12 Aug 2026
A4: PURPOSE
A5: This workbook is the Evidence Matrix called for in the Rev 5 research plan and the Version 2 execution plan.
A6: It converts the integrated source architecture (Rev 5 Section 3B, the ten areas) into a chartable database.
A7: The 'Evidence Matrix' sheet is SEEDED: descriptive/mapping columns are pre-filled from the plan; evidential
A8: columns are left as [to chart] so charting still happens per source. Council rule: citation is not evidence.
A10: HOW TO USE (Stage 3 charting)
A11: 1. Work top-to-bottom in the Rev 5 priority reading order (Phase 1 first: rows tagged Priority A in Areas 1,2,3,6).
A12: 2. For each source, retrieve it, then fill the [to chart] cells: Key Finding, Effect Size, Limitations, Disconfirming.
A13: 3. Set Verification Status to 'Verified' once the DOI/citation is confirmed (Section 4.6 discipline).
A14: 4. A source is not 'charted' until columns L-O are complete AND Verification = Verified.
... A29: KEYS
A30: PRIORITY | B30: A = load-bearing (chart early) | B = strong supporting | C = contextual / bridge
A31: FUNCTION | B31: TELOS defines purpose | MECHANISM how it works | WARNING failure modes | METHOD procedure | DESIGN artifact guidance | MEASURE operationalization | CRITIQUE challenges assumptions
A32: AREAS 1-10 | B32: 1 Philosophy of tech beyond Hui | 2 Personal informatics/QS critique | 3 Critical HCI agency/moral friction | 4 Environmental psych place/restoration | 5 Phenomenological methods | 6 Automation ethics/autonomy | 7 AI offloading/self-regulation | 8 Ritual/symbolic practice | 9 Work productivity ecology | 10 Cross-cultural autonomy/technodiversity
A33: FAILURE MODES | B33: CF-1 productivity without moral gain | CF-2 metric capture | CF-3 internalized coercion | CF-4 tech paternalism | CF-5 attentional extraction | CF-6 ecological flattening | CF-7 ritual hollowing | CF-8 universalization | CF-9 reversibility loss | CF-10 false cosmotechnics
A34: WORKSTREAMS | B34: WS-A Motivation | WS-B Willpower/structure | WS-C Emotion regulation | WS-D Behavioral diagnosis | WS-E Environmental ecology | WS-F Phenomenology | WS-G Reference/consequence | WS-H Digital/temporal | WS-I Adverse effects | WS-J Moderators | WS-K Cosmotechnics | WS-L Moral ecology
A36: SOURCE DISCOVERY UPDATE v1
A37: Eight columns were added to Evidence Matrix: Readable Source URL, Source Landing URL, Access Type, Source Discovery Status, Discovery Notes, Suggested Search Query, Scholar/Web Search URL, and Source Checked Date. Direct links were added only where discovered in this first pass; all other rows are queued and not verified.

Sheet Source Discovery Log
A1: Field | B1: Value
A2: Run purpose | B2: First-pass readable-source locator to make future context-window handoffs easier.
A3: Run date | B3: 2026-08-13
A4: Rows with direct readable source added | B4: 13
A5: Companion Hui 2024 row added | B5: Yes, as HUI-2024, because it materially grounds the v6 design memo.
A6: Default for unsearched rows | B6: Queued with suggested web query; not marked verified.
A7: Charting rule preserved | B7: A row is not charted until evidential notes are completed and verification is confirmed.
A8: Next recommended search pass | B8: Continue Priority A rows in Areas 1, 2, 3, 6, then core motivation/method sources.

Sheet Dashboard
A1: MONSTARE EVIDENCE MATRIX — DASHBOARD
A2: Live counts recalculated from the Evidence Matrix sheet. Charting progress = Verified rows.
A4: TOTALS | F4: COSMOTECHNIC RELEVANCE
A5: Total sources | B5: =COUNTA('Evidence Matrix'!A2:A129) -> 128 | F5: Level | H5: Count
A6: Priority A (load-bearing) | B6: =COUNTIF('Evidence Matrix'!F2:F129,"A") -> 0 | F6: high | H6: =COUNTIF('Evidence Matrix'!K2:K129,"high") -> 0
A7: Priority B | B7: =COUNTIF('Evidence Matrix'!F2:F129,"B") -> 0 | F7: medium | H7: =COUNTIF('Evidence Matrix'!K2:K129,"medium") -> 0
A8: Priority C | B8: =COUNTIF('Evidence Matrix'!F2:F129,"C") -> 0 | F8: low | H8: =COUNTIF('Evidence Matrix'!K2:K129,"low") -> 0
A9: Verified (charted) | B9: =COUNTIF('Evidence Matrix'!C2:C129,"Verified") -> 0
A10: Pending | B10: =COUNTIF('Evidence Matrix'!C2:C129,"Pending") -> 0
A11: % charted | B11: =IF(B5=0,0,B9/B5) -> 0
A13: BY SOURCE AREA (1-10) | F13: BY WORKSTREAM
A14: Area | B14: Description | C14: Sources | D14: Verified | F14: WS | G14: Focus | H14: Sources
A15: 1 | B15: Philosophy of technology beyond Hui | C15: =COUNTIF('Evidence Matrix'!D2:D129,1) -> 0 | D15: =COUNTIFS('Evidence Matrix'!D2:D129,1,'Evidence Matrix'!C2:C129,"Verified") -> 0 | F15: WS-A | G15: Motivational quality | H15: =COUNTIF('Evidence Matrix'!E2:E129,"WS-A") -> 0
A16: 2 | B16: Personal informatics / QS critique | C16: =COUNTIF('Evidence Matrix'!D2:D129,2) -> 0 | D16: =COUNTIFS('Evidence Matrix'!D2:D129,2,'Evidence Matrix'!C2:C129,"Verified") -> 0 | F16: WS-B | G16: Willpower / structure | H16: =COUNTIF('Evidence Matrix'!E2:E129,"WS-B") -> 0
A17: 3 | B17: Critical HCI: agency & moral friction | C17: =COUNTIF('Evidence Matrix'!D2:D129,3) -> 0 | D17: =COUNTIFS('Evidence Matrix'!D2:D129,3,'Evidence Matrix'!C2:C129,"Verified") -> 0 | F17: WS-C | G17: Emotion regulation | H17: =COUNTIF('Evidence Matrix'!E2:E129,"WS-C") -> 0
A18: 4 | B18: Environmental psychology: place & restoration | C18: =COUNTIF('Evidence Matrix'!D2:D129,4) -> 0 | D18: =COUNTIFS('Evidence Matrix'!D2:D129,4,'Evidence Matrix'!C2:C129,"Verified") -> 0 | F18: WS-D | G18: Behavioral diagnosis | H18: =COUNTIF('Evidence Matrix'!E2:E129,"WS-D") -> 0
A19: 5 | B19: Phenomenological methods | C19: =COUNTIF('Evidence Matrix'!D2:D129,5) -> 0 | D19: =COUNTIFS('Evidence Matrix'!D2:D129,5,'Evidence Matrix'!C2:C129,"Verified") -> 0 | F19: WS-E | G19: Environmental ecology | H19: =COUNTIF('Evidence Matrix'!E2:E129,"WS-E") -> 0
A20: 6 | B20: Automation ethics & autonomy | C20: =COUNTIF('Evidence Matrix'!D2:D129,6) -> 0 | D20: =COUNTIFS('Evidence Matrix'!D2:D129,6,'Evidence Matrix'!C2:C129,"Verified") -> 0 | F20: WS-F | G20: Phenomenology | H20: =COUNTIF('Evidence Matrix'!E2:E129,"WS-F") -> 0
A21: 7 | B21: AI offloading & self-regulation | C21: =COUNTIF('Evidence Matrix'!D2:D129,7) -> 0 | D21: =COUNTIFS('Evidence Matrix'!D2:D129,7,'Evidence Matrix'!C2:C129,"Verified") -> 0 | F21: WS-G | G21: Reference / consequence | H21: =COUNTIF('Evidence Matrix'!E2:E129,"WS-G") -> 0
A22: 8 | B22: Ritual & symbolic practice | C22: =COUNTIF('Evidence Matrix'!D2:D129,8) -> 0 | D22: =COUNTIFS('Evidence Matrix'!D2:D129,8,'Evidence Matrix'!C2:C129,"Verified") -> 0 | F22: WS-H | G22: Digital / temporal | H22: =COUNTIF('Evidence Matrix'!E2:E129,"WS-H") -> 0
A23: 9 | B23: Work productivity ecology | C23: =COUNTIF('Evidence Matrix'!D2:D129,9) -> 0 | D23: =COUNTIFS('Evidence Matrix'!D2:D129,9,'Evidence Matrix'!C2:C129,"Verified") -> 0 | F23: WS-I | G23: Adverse effects | H23: =COUNTIF('Evidence Matrix'!E2:E129,"WS-I") -> 0
A24: 10 | B24: Cross-cultural autonomy & technodiversity | C24: =COUNTIF('Evidence Matrix'!D2:D129,10) -> 0 | D24: =COUNTIFS('Evidence Matrix'!D2:D129,10,'Evidence Matrix'!C2:C129,"Verified") -> 0 | F24: WS-J | G24: Moderators | H24: =COUNTIF('Evidence Matrix'!E2:E129,"WS-J") -> 0
A25: core+methods | B25: Carried core theory & methods (Rev 3-4) | C25: =B5-SUM(C15:C24) -> 128 | D25: =COUNTIF('Evidence Matrix'!C2:C129,"Verified")-SUM(D15:D24) -> 0 | F25: WS-K | G25: Cosmotechnics | H25: =COUNTIF('Evidence Matrix'!E2:E129,"WS-K") -> 0
F26: WS-L | G26: Moral ecology | H26: =COUNTIF('Evidence Matrix'!E2:E129,"WS-L") -> 0

Sheet Evidence Matrix
A1: ID | B1: Citation | C1: Readable Source URL | D1: Source Landing URL | E1: Access Type | F1: Source Discovery Status | G1: Discovery Notes | H1: Suggested Search Query | I1: Scholar/Web Search URL | J1: Source Checked Date | K1: Verif. | L1: Area | M1: WS | N1: Pri | O1: Function | P1: Evidence Type | Q1: Domain | R1: Causal Status | S1: Cosmo Rel. | T1: Key Finding / Thesis | U1: Effect Size / Strength | V1: Limitations | W1: Disconfirming Implication | X1: H1 | Y1: H2 | Z1: Design Implication | AA1: Cosmotechnic Implication | AB1: Fail Mode | AC1: Artifact Affected | AD1: Open Charge | AE1: Staleness Domain | AF1: Re-search Interval | AG1: Last Verified Date | AH1: Re-search By | AI1: Staleness Status
A2: CORE-01 | B2: Ryan & Deci — Self-Determination Theory (needs) | C2: https://selfdeterminationtheory.org/SDT/documents/2000_RyanDeci_SDT.pdf | D2: https://selfdeterminationtheory.org/theory/ | E2: Open PDF / alternate SDT primary paper | F2: Readable source found - verify exact intended source before charting | G2: Matrix row names the SDT needs construct broadly. This link is Ryan & Deci 2000 SDT overview; exact 2017 book is also discoverable but not necessarily legally open in full. Use this as an accessible primary anchor unless the project requires the 2017 Guilford book. | H2: Ryan & Deci — Self-Determination Theory (needs) pdf DOI readable source | I2: https://www.google.com/search?q=Ryan+%26+Deci+%E2%80%94+Self-Determination+Theory+%28needs%29+pdf+DOI+readable+source | J2: 2026-08-13 | K2: Pending | L2: core | M2: WS-A | N2: A | O2: TELOS/MECHANISM | P2: theoretical | Q2: motivation | R2: conceptual | S2: high | T2: Autonomy, competence, relatedness convert pressure into durable, autonomous motivation. | U2: [to chart] | V2: [to chart] | W2: [to chart] | X2: yes | Y2: yes | Z2: Ground the need-support profile (M2); define autonomous vs controlled motivation. | AA2: Motivation quality is the substrate of moral authorship, not just output. | AB2: CF-3 | AC2: Agency & Autonomy Checklist | AD2: OC-8 | AE2: General supporting source | AF2: 36 months | AG2: 2026-08-13 | AH2: 2029-08-13 | AI2: Current - re-search on schedule
A3: CORE-02 | B3: Markland, Ryan, Tobin & Rollnick — MI + SDT | C3: https://selfdeterminationtheory.org/SDT/documents/2005_MarklandRyanTobinRollnick_MotivationalInterviewing.pdf | D3: https://pure.ewha.ac.kr/en/publications/motivational-interviewing-and-self-determination-theory/ | E3: Open PDF | F3: Readable source found | G3: DOI identified in search result as 10.1521/jscp.2005.24.6.811. | H3: Markland, Ryan, Tobin & Rollnick — MI + SDT pdf DOI readable source | I3: https://www.google.com/search?q=Markland%2C+Ryan%2C+Tobin+%26+Rollnick+%E2%80%94+MI+%2B+SDT+pdf+DOI+readable+source | J3: 2026-08-13 | K3: Pending | L3: core | M3: WS-A | N3: A | O3: MECHANISM | P3: theoretical | Q3: motivation | R3: conceptual | S3: medium | T3: MI is a social-environmental support for autonomy and internalization. | U3: [to chart] | V3: [to chart] | W3: [to chart] | X3: yes | Y3: partial | Z3: Autonomy-preserving conversational method for ambivalence. | AA3: Non-coercive change as cosmotechnic constraint. | AB3: CF-3 | AC3: Self-Nudging Design Card | AE3: General supporting source | AF3: 36 months | AG3: 2026-08-13 | AH3: 2029-08-13 | AI3: Current - re-search on schedule
A4: CORE-03 | B4: Vansteenkiste, Williams & Resnicow — SDT/MI integration | C4: https://selfdeterminationtheory.org/wp-content/uploads/2014/04/2012_VansteenkisteWilliamsResnicow_InterventionDevelopment_IJBNPA.pdf | D4: https://link.springer.com/article/10.1186/1479-5868-9-23 | E4: Open PDF | F4: Located - readable source | G4: Priority B pass: open PDF located via SDT repository; Springer landing recorded. | H4: Vansteenkiste, Williams & Resnicow — SDT/MI integration pdf DOI readable source | I4: https://www.google.com/search?q=Vansteenkiste%2C+Williams+%26+Resnicow+%E2%80%94+SDT%2FMI+integration+pdf+DOI+readable+source | J4: 2026-08-13 | K4: Located (not charted) | L4: core | M4: WS-A | N4: B | O4: MECHANISM | P4: review | Q4: motivation | R4: conceptual | S4: medium | T4: Autonomy/volition is the shared process principle across SDT and MI. | U4: [to chart] | V4: [to chart] | W4: [to chart] | X4: yes | Y4: partial | Z4: Unify motivational method around volition. | AA4: Volition over compliance. | AB4: CF-3 | AC4: Self-Nudging Design Card | AE4: Empirical / applied research | AF4: 24 months | AG4: 2026-08-13 | AH4: 2028-08-13 | AI4: Current - re-search on schedule
A5: CORE-04 | B5: Bandura — Self-efficacy | C5: https://www.uky.edu/~eushe2/Bandura/Bandura1997SE.pdf | D5: https://psycnet.apa.org/record/1997-08589-000 | E5: Open PDF / landing | F5: Located - readable source | G5: PDF located for Bandura self-efficacy book excerpt/chapter. Verify edition/page details during charting. | H5: Bandura — Self-efficacy pdf DOI readable source | I5: https://www.google.com/search?q=Bandura+%E2%80%94+Self-efficacy+pdf+DOI+readable+source | J5: 2026-08-13 | K5: Located (not charted) | L5: core | M5: WS-A | N5: A | O5: MECHANISM | P5: theoretical | Q5: motivation | R5: causal | S5: medium | T5: Domain-specific efficacy; mastery is the strongest source; reciprocal with performance. | U5: [to chart] | V5: [to chart] | W5: [to chart] | X5: yes | Y5: partial | Z5: Build efficacy via early mastery, not exhortation (M2). | AA5: Competence as capacity for good action. | AC5: Motivation Crowding Watch Card | AE5: General supporting source | AF5: 36 months | AG5: 2026-08-13 | AH5: 2029-08-13 | AI5: Current - re-search on schedule
A6: CORE-05 | B6: Deci, Koestner & Ryan — extrinsic rewards meta-analysis | C6: https://selfdeterminationtheory.org/wp-content/uploads/2014/04/1999_DeciKoestnerRyan_Meta.pdf | D6: https://doi.org/10.1037/0033-2909.125.6.627 | E6: Open PDF | F6: Readable source found | G6: Search results report meta-analysis of 128 studies and DOI 10.1037/0033-2909.125.6.627. | H6: Deci, Koestner & Ryan — extrinsic rewards meta-analysis pdf DOI readable source | I6: https://www.google.com/search?q=Deci%2C+Koestner+%26+Ryan+%E2%80%94+extrinsic+rewards+meta-analysis+pdf+DOI+readable+source | J6: 2026-08-13 | K6: Pending | L6: core | M6: WS-I | N6: A | O6: WARNING | P6: review | Q6: motivation | R6: causal | S6: high | T6: Contingent tangible rewards undermine intrinsic motivation; positive feedback enhances. | U6: [to chart] | V6: [to chart] | W6: [to chart] | X6: yes | Y6: yes | Z6: Core H1c crowding evidence; sets c_C in the model. | AA6: Buying compliance can cost autonomy = cosmotechnic failure. | AB6: CF-1/CF-3 | AC6: Motivation Crowding Watch Card | AD6: OC-2 | AE6: Empirical / applied research | AF6: 24 months | AG6: 2026-08-13 | AH6: 2028-08-13 | AI6: Current - re-search on schedule
A7: CORE-06 | B7: Frey & Jegen — motivation crowding theory | C7: https://www.bsfrey.ch/articles/C_317_01.pdf | D7: https://doi.org/10.1023/A:1017564312479 | E7: Open PDF / DOI landing | F7: Located - readable source | G7: Readable author PDF located for motivation crowding theory. | H7: Frey & Jegen — motivation crowding theory pdf DOI readable source | I7: https://www.google.com/search?q=Frey+%26+Jegen+%E2%80%94+motivation+crowding+theory+pdf+DOI+readable+source | J7: 2026-08-13 | K7: Located (not charted) | L7: core | M7: WS-I | N7: A | O7: WARNING | P7: review | Q7: economics/psych | R7: correlational | S7: high | T7: External incentives can crowd out intrinsic motivation (crowding-out effect). | U7: [to chart] | V7: [to chart] | W7: [to chart] | X7: yes | Y7: yes | Z7: Cross-disciplinary confirmation of crowding risk. | AA7: Incentive design is morally consequential. | AB7: CF-1/CF-3 | AC7: Motivation Crowding Watch Card | AD7: OC-2 | AE7: Empirical / applied research | AF7: 24 months | AG7: 2026-08-13 | AH7: 2028-08-13 | AI7: Current - re-search on schedule
A8: CORE-07 | B8: Lepper, Greene & Nisbett — over-justification | C8: https://selfdeterminationtheory.org/SDT/documents/1973_LepperGreeneNisbett.pdf | D8: https://psycnet.apa.org/doi/10.1037/h0035519 | E8: Open PDF / DOI landing | F8: Located - readable source | G8: Readable SDT archive PDF for classic overjustification paper. | H8: Lepper, Greene & Nisbett — over-justification pdf DOI readable source | I8: https://www.google.com/search?q=Lepper%2C+Greene+%26+Nisbett+%E2%80%94+over-justification+pdf+DOI+readable+source | J8: 2026-08-13 | K8: Located (not charted) | L8: core | M8: WS-I | N8: A | O8: WARNING | P8: empirical | Q8: psychology | R8: causal | S8: high | T8: Expected reward for intrinsically interesting activity reduces later interest. | U8: [to chart] | V8: [to chart] | W8: [to chart] | X8: yes | Y8: partial | Z8: Original demonstration; anchors the tip-over intuition. | AA8: Reward can hollow meaning. | AB8: CF-3 | AC8: Motivation Crowding Watch Card | AE8: Empirical / applied research | AF8: 24 months | AG8: 2026-08-13 | AH8: 2028-08-13 | AI8: Current - re-search on schedule
A9: CORE-08 | B9: Reijula & Hertwig — self-nudging & citizen choice architect | C9: https://nudging-for-sdgs.eu/wp-content/uploads/2023/12/Self-nudging-and-the-citizen-choice-architect.pdf | D9: https://researchportal.helsinki.fi/en/publications/self-nudging-and-the-citizen-choice-architect | E9: Open PDF / publisher or postprint also available | F9: Readable source found | G9: Search results identify DOI 10.1017/bpp.2020.5 and OSF DOI 10.31235/osf.io/24dwn. | H9: Reijula & Hertwig — self-nudging & citizen choice architect pdf DOI readable source | I9: https://www.google.com/search?q=Reijula+%26+Hertwig+%E2%80%94+self-nudging+%26+citizen+choice+architect+pdf+DOI+readable+source | J9: 2026-08-13 | K9: Pending | L9: core | M9: WS-D | N9: A | O9: DESIGN/MECHANISM | P9: theoretical | Q9: behavioral policy | R9: conceptual | S9: high | T9: The person as choice-architect of their own proximal environment preserves internal PLOC. | U9: [to chart] | V9: [to chart] | W9: [to chart] | X9: yes | Y9: yes | Z9: Central mechanism for authorship (lambda); M4d. | AA9: Self-authorship as vehicle for autonomy, but not sufficient. | AB9: CF-3 | AC9: Self-Nudging Design Card | AD9: OC-6 | AE9: General supporting source | AF9: 36 months | AG9: 2026-08-13 | AH9: 2029-08-13 | AI9: Current - re-search on schedule
A10: CORE-09 | B10: Carver & Scheier — self-regulation / control theory | C10: https://stuff.mit.edu/afs/athena/course/9/9.00/readings/CarverScheier1982.pdf | D10: https://doi.org/10.1037/0033-295X.89.2.111 | E10: Open PDF / DOI landing | F10: Located - readable source | G10: Readable PDF of feedback/self-regulation control theory located. | H10: Carver & Scheier — self-regulation / control theory pdf DOI readable source | I10: https://www.google.com/search?q=Carver+%26+Scheier+%E2%80%94+self-regulation+%2F+control+theory+pdf+DOI+readable+source | J10: 2026-08-13 | K10: Located (not charted) | L10: core | M10: WS-G | N10: A | O10: MECHANISM | P10: theoretical | Q10: psychology | R10: conceptual | S10: medium | T10: Behavior is a feedback loop: input, comparator vs reference, output, environment. | U10: [to chart] | V10: [to chart] | W10: [to chart] | X10: yes | Y10: partial | Z10: Loop design (M4b); feedback quality is the lever. | AA10: Loops encode values; what they make salient matters. | AC10: Arousal/Flow/Task-Switching Layer | AD10: OC-4 | AE10: Empirical / applied research | AF10: 24 months | AG10: 2026-08-13 | AH10: 2028-08-13 | AI10: Current - re-search on schedule
A11: CORE-10 | B11: Locke & Latham — goal-setting theory | C11: https://home.ubalt.edu/tmitch/642/Articles%20syllabus/Locke%20Latham%202002%20building%20theory%20goal%20setting%20Am%20Psych.pdf | D11: https://psycnet.apa.org/record/2002-10108-003 | E11: Open PDF / landing | F11: Located - readable source | G11: Readable PDF for Locke & Latham goal-setting theory article located. | H11: Locke & Latham — goal-setting theory pdf DOI readable source | I11: https://www.google.com/search?q=Locke+%26+Latham+%E2%80%94+goal-setting+theory+pdf+DOI+readable+source | J11: 2026-08-13 | K11: Located (not charted) | L11: core | M11: WS-G | N11: A | O11: MECHANISM | P11: review | Q11: org psych | R11: causal | S11: medium | T11: Specific/difficult goals beat 'do your best' via four mechanisms, five moderators. | U11: [to chart] | V11: [to chart] | W11: [to chart] | X11: yes | Y11: partial | Z11: Reference-setting (M4a); learning vs performance framing. | AA11: Goals must be morally/ecologically fit, not just efficient. | AB11: CF-1 | AC11: Monstare Protocol vNext | AE11: Empirical / applied research | AF11: 24 months | AG11: 2026-08-13 | AH11: 2028-08-13 | AI11: Current - re-search on schedule
A12: CORE-11 | B12: Ordonez et al. — Goals Gone Wild | C12: https://www.hbs.edu/ris/Publication%20Files/09-083.pdf | D12: https://www.jstor.org/stable/27747490 | E12: Open PDF / JSTOR landing | F12: Located - readable source | G12: Priority B pass: HBS working paper PDF and JSTOR landing located. | H12: Ordonez et al. — Goals Gone Wild pdf DOI readable source | I12: https://www.google.com/search?q=Ordonez+et+al.+%E2%80%94+Goals+Gone+Wild+pdf+DOI+readable+source | J12: 2026-08-13 | K12: Located (not charted) | L12: core | M12: WS-G | N12: B | O12: WARNING | P12: review | Q12: org psych | R12: conceptual | S12: medium | T12: Aggressive goals cause narrowing, stress, shortcuts, reduced intrinsic interest. | U12: [to chart] | V12: [to chart] | W12: [to chart] | X12: partial | Y12: yes | Z12: Goal failure modes; guardrails on M4a. | AA12: Goal narrowing as moral flattening. | AB12: CF-1 | AC12: Design Veto Catalogue | AE12: Empirical / applied research | AF12: 24 months | AG12: 2026-08-13 | AH12: 2028-08-13 | AI12: Current - re-search on schedule
A13: CORE-12 | B13: Ferster & Skinner — Schedules of Reinforcement | C13: https://archive.org/details/schedulesofreinf0000fers | D13: https://www.worldcat.org/title/191941 | E13: Archive lending / catalog landing | F13: Located - restricted readable | G13: Archive lending page located; no stable open full text found in pass. | H13: Ferster & Skinner — Schedules of Reinforcement pdf DOI readable source | I13: https://www.google.com/search?q=Ferster+%26+Skinner+%E2%80%94+Schedules+of+Reinforcement+pdf+DOI+readable+source | J13: 2026-08-13 | K13: Located (not charted) | L13: core | M13: WS-G | N13: A | O13: MECHANISM | P13: empirical | Q13: behavior analysis | R13: causal | S13: medium | T13: Variable-ratio schedules are most extinction-resistant. | U13: [to chart] | V13: [to chart] | W13: [to chart] | X13: yes | Y13: no | Z13: Contingency/schedule design (M4c). | AA13: Slot-machine schedules risk dependency. | AB13: CF-3 | AC13: Design Veto Catalogue | AE13: Empirical / applied research | AF13: 24 months | AG13: 2026-08-13 | AH13: 2028-08-13 | AI13: Current - located, access/fit caveat
A14: CORE-13 | B14: Staddon & Cerutti — operant conditioning review | C14: https://pmc.ncbi.nlm.nih.gov/articles/PMC1473025/ | D14: https://scholars.duke.edu/publication/915302 | E14: Open full text / DOI landing | F14: Located - readable source | G14: Priority B pass: PMC full text for Annual Review chapter located. | H14: Staddon & Cerutti — operant conditioning review pdf DOI readable source | I14: https://www.google.com/search?q=Staddon+%26+Cerutti+%E2%80%94+operant+conditioning+review+pdf+DOI+readable+source | J14: 2026-08-13 | K14: Located (not charted) | L14: core | M14: WS-G | N14: B | O14: MECHANISM/REVIEW | P14: review | Q14: behavior analysis | R14: causal | S14: low | T14: Matching law; consequence-engineering is neither simple nor cost-free. | U14: [to chart] | V14: [to chart] | W14: [to chart] | X14: yes | Y14: no | Z14: Temper naive contingency design. | AA14: Consequence engineering has hidden costs. | AB14: CF-3 | AC14: Motivation Crowding Watch Card | AE14: Empirical / applied research | AF14: 24 months | AG14: 2026-08-13 | AH14: 2028-08-13 | AI14: Current - re-search on schedule
A15: CORE-14 | B15: Clark & Chalmers — The Extended Mind | C15: https://consc.net/papers/extended.html | D15: https://doi.org/10.1093/019823682X.003.0002 | E15: Author HTML / DOI landing | F15: Located - readable source | G15: Readable author version located for The Extended Mind. | H15: Clark & Chalmers — The Extended Mind pdf DOI readable source | I15: https://www.google.com/search?q=Clark+%26+Chalmers+%E2%80%94+The+Extended+Mind+pdf+DOI+readable+source | J15: 2026-08-13 | K15: Located (not charted) | L15: core | M15: WS-E | N15: A | O15: TELOS | P15: philosophical | Q15: cognitive science | R15: conceptual | S15: high | T15: Cognition is partly constituted by body, tools, and environment. | U15: [to chart] | V15: [to chart] | W15: [to chart] | X15: partial | Y15: yes | Z15: Warrant for treating environment design as cognitive design. | AA15: Cognitive design is also world-design. | AC15: Digital Capture Architecture | AE15: Philosophical / historical / theoretical | AF15: 60 months | AG15: 2026-08-13 | AH15: 2031-08-13 | AI15: Current - re-search on schedule
A16: CORE-15 | B16: Gross — emotion regulation timeline | C16: https://spl.stanford.edu/pdfs/1998%20Gross%20-%20The%20Emerging%20Field%20of%20Emotion%20Regulation.pdf | D16: https://doi.org/10.1037/1089-2680.2.3.271 | E16: Open PDF / DOI landing | F16: Located - readable source | G16: Readable PDF located for Gross emotion regulation review. | H16: Gross — emotion regulation timeline pdf DOI readable source | I16: https://www.google.com/search?q=Gross+%E2%80%94+emotion+regulation+timeline+pdf+DOI+readable+source | J16: 2026-08-13 | K16: Located (not charted) | L16: core | M16: WS-C | N16: A | O16: MECHANISM | P16: theoretical | Q16: affective science | R16: causal | S16: medium | T16: Antecedent regulation (situation selection/modification) is cheaper than response repair. | U16: [to chart] | V16: [to chart] | W16: [to chart] | X16: yes | Y16: partial | Z16: Locate intervention point (M3); antecedent design. | AA16: Regulation without numbing meaningful signals. | AC16: Monstare Protocol vNext | AE16: General supporting source | AF16: 36 months | AG16: 2026-08-13 | AH16: 2029-08-13 | AI16: Current - re-search on schedule
A17: CORE-16 | B17: Csikszentmihalyi — Flow | C17: https://archive.org/details/flowpsychologyof0000csik | D17: https://www.harpercollins.com/products/flow-mihaly-csikszentmihalyi | E17: Archive lending / publisher landing | F17: Located - restricted readable | G17: Archive lending and publisher page located; charting should use borrowed/legal copy. | H17: Csikszentmihalyi — Flow pdf DOI readable source | I17: https://www.google.com/search?q=Csikszentmihalyi+%E2%80%94+Flow+pdf+DOI+readable+source | J17: 2026-08-13 | K17: Located (not charted) | L17: core | M17: WS-E | N17: A | O17: MECHANISM | P17: theoretical | Q17: psychology | R17: conceptual | S17: medium | T17: Challenge-skill balance, clear goals, feedback yield absorbed engagement. | U17: [to chart] | V17: [to chart] | W17: [to chart] | X17: yes | Y17: partial | Z17: Conditions suppliable; state not forceable. | AA17: Flow as attunement, not extraction. | AC17: Arousal/Flow/Task-Switching Layer | AE17: Empirical / applied research | AF17: 24 months | AG17: 2026-08-13 | AH17: 2028-08-13 | AI17: Current - located, access/fit caveat
A18: CORE-17 | B18: Kazdin — Single-Case Research Designs | C18: https://archive.org/details/singlecaseresear00alan | D18: https://books.google.com/books/about/Single_Case_Research_Designs.html?id=RvrTEQAAQBAJ | E18: Borrow/controlled digital lending or book preview | F18: Readable source located - access controlled | G18: Exact edition may vary. Archive link is 1982 access-restricted scan; Google Books entry shows later third edition. Treat as access-controlled book, not open article. | H18: Kazdin — Single-Case Research Designs pdf DOI readable source | I18: https://www.google.com/search?q=Kazdin+%E2%80%94+Single-Case+Research+Designs+pdf+DOI+readable+source | J18: 2026-08-13 | K18: Pending | L18: methods | M18: methods | N18: A | O18: METHOD | P18: methods | Q18: research methods | R18: conceptual | S18: low | T18: Multiple-baseline logic controls history/maturation without a control person. | U18: [to chart] | V18: [to chart] | W18: [to chart] | X18: partial | Y18: no | Z18: Spine of the Tier-C pilot (SCED). | AA18: Rigorous N-of-1 inference vs false generalization. | AC18: SCED Phase Plan | AD18: OC-5 | AE18: Methods / reporting standards | AF18: 36 months | AG18: 2026-08-13 | AH18: 2029-08-13 | AI18: Current - re-search on schedule
A19: CORE-18 | B19: Tate et al. — SCRIBE 2016 reporting guideline | C19: https://www.equator-network.org/reporting-guidelines/scribe-statement/ | D19: https://academic.oup.com/ptj/article/96/7/e1/2864911 | E19: Open guideline page / article page / checklist PDF | F19: Readable source found | G19: EQUATOR page supplies full bibliographic reference, links, and the 26-item SCRIBE 2016 guideline. | H19: Tate et al. — SCRIBE 2016 reporting guideline pdf DOI readable source | I19: https://www.google.com/search?q=Tate+et+al.+%E2%80%94+SCRIBE+2016+reporting+guideline+pdf+DOI+readable+source | J19: 2026-08-13 | K19: Pending | L19: methods | M19: methods | N19: A | O19: METHOD | P19: methods | Q19: research methods | R19: conceptual | S19: low | T19: 26-item checklist for single-case behavioral intervention reporting. | U19: [to chart] | V19: [to chart] | W19: [to chart] | X19: partial | Y19: no | Z19: Governs SCED reporting quality. | AA19: Transparency as anti-self-deception. | AC19: Preregistration Packet | AD19: OC-5 | AE19: Methods / reporting standards | AF19: 36 months | AG19: 2026-08-13 | AH19: 2029-08-13 | AI19: Current - re-search on schedule
A20: CORE-19 | B20: Klasnja et al. — Micro-randomized trials | C20: https://pmc.ncbi.nlm.nih.gov/articles/PMC5820391/ | D20: https://doi.org/10.1016/j.cct.2015.07.003 | E20: Open full text / DOI landing | F20: Located - readable source | G20: PMC open full text located for micro-randomized trials paper. | H20: Klasnja et al. — Micro-randomized trials pdf DOI readable source | I20: https://www.google.com/search?q=Klasnja+et+al.+%E2%80%94+Micro-randomized+trials+pdf+DOI+readable+source | J20: 2026-08-13 | K20: Located (not charted) | L20: methods | M20: methods | N20: A | O20: METHOD | P20: methods | Q20: research methods | R20: causal | S20: low | T20: MRT estimates proximal causal effects and time-varying moderation. | U20: [to chart] | V20: [to chart] | W20: [to chart] | X20: partial | Y20: no | Z20: Best for high-frequency digital prompts/JITAI. | AA20: Rigor for the digital channel. | AC20: Digital Capture Architecture | AE20: Methods / reporting standards | AF20: 36 months | AG20: 2026-08-13 | AH20: 2029-08-13 | AI20: Current - re-search on schedule
A21: CORE-20 | B21: Collins — Multiphase Optimization Strategy (MOST) | C21: https://methodology.psu.edu/wp-content/uploads/2020/05/Collins-2018-MOST-Overview.pdf | D21: https://www.springer.com/gp/book/9783319722054 | E21: Open PDF / book landing | F21: Located - readable source | G21: Readable MOST overview located; verify if matrix should reference book vs overview during charting. | H21: Collins — Multiphase Optimization Strategy (MOST) pdf DOI readable source | I21: https://www.google.com/search?q=Collins+%E2%80%94+Multiphase+Optimization+Strategy+%28MOST%29+pdf+DOI+readable+source | J21: 2026-08-13 | K21: Located (not charted) | L21: methods | M21: methods | N21: A | O21: METHOD | P21: methods | Q21: research methods | R21: causal | S21: low | T21: Factorial screening separates intervention-component effects. | U21: [to chart] | V21: [to chart] | W21: [to chart] | X21: partial | Y21: no | Z21: Channel attribution once components defined. | AA21: Avoid confounding the whole ecology. | AC21: Intervention Component Library | AD21: OC-3 | AE21: Methods / reporting standards | AF21: 36 months | AG21: 2026-08-13 | AH21: 2029-08-13 | AI21: Current - re-search on schedule
A22: A1-01 | B22: Hui — The Question Concerning Technology in China | C22: https://ia800505.us.archive.org/20/items/cyclonopedia-negarestani-reza/The_Question_Concerning_Technology_in_China--_Yuk_Hui.pdf | D22: https://brill.com/previewpdf/view/journals/dias/4/3/article-p316_316.xml | E22: PDF found / copyright status should be reviewed before relying on full-text copy | F22: Readable source found - verify rights/edition | G22: Use legally obtained copy if possible. Existing design memo relies more centrally on Hui 2024, which is open access. | H22: Hui — The Question Concerning Technology in China pdf DOI readable source | I22: https://www.google.com/search?q=Hui+%E2%80%94+The+Question+Concerning+Technology+in+China+pdf+DOI+readable+source | J22: 2026-08-13 | K22: Pending | L22: 1 | M22: WS-K | N22: A | O22: TELOS | P22: philosophical | Q22: philosophy of tech | R22: conceptual | S22: high | T22: Technology is not anthropologically universal; cosmotechnics binds cosmic + moral + technical. | U22: [to chart] | V22: [to chart] | W22: [to chart] | X22: partial | Y22: yes | Z22: Governing telos (layer 2.13); the plan's horizon. | AA22: Sets the whole cosmotechnic criterion. | AB22: CF-10 | AC22: Cosmotechnic Audit Card | AD22: OC-7 | AE22: Philosophical / historical / theoretical | AF22: 60 months | AG22: 2026-08-13 | AH22: 2031-08-13 | AI22: Current - re-search on schedule
A23: A1-02 | B23: Hui — Cosmotechnics as Cosmopolitics | C23: https://www.e-flux.com/journal/86/161887/cosmotechnics-as-cosmopolitics/ | D23: https://digitalmilieu.net/1248/cosmotechnics-as-cosmopolitics/ | E23: Open HTML | F23: Located - readable source | G23: Priority B pass: e-flux full text and author page located. | H23: Hui — Cosmotechnics as Cosmopolitics pdf DOI readable source | I23: https://www.google.com/search?q=Hui+%E2%80%94+Cosmotechnics+as+Cosmopolitics+pdf+DOI+readable+source | J23: 2026-08-13 | K23: Located (not charted) | L23: 10 | M23: WS-K | N23: B | O23: TELOS/CRITIQUE | P23: philosophical | Q23: philosophy of tech | R23: conceptual | S23: high | T23: Resists unilateral globalization of one technical worldview; technodiversity. | U23: [to chart] | V23: [to chart] | W23: [to chart] | X23: no | Y23: yes | Z23: Support personal technodiversity. | AA23: Refuse one productivity ontology. | AB23: CF-8 | AC23: Technodiversity & Cultural Fit Sheet | AD23: OC-11 | AE23: Philosophical / historical / theoretical | AF23: 60 months | AG23: 2026-08-13 | AH23: 2031-08-13 | AI23: Current - re-search on schedule
A24: A1-03 | B24: Hui — Art and Cosmotechnics | C24: https://www.e-flux.com/books/327526/art-and-cosmotechnics | D24: https://www.upress.umn.edu/9781517909543/art-and-cosmotechnics/ | E24: Publisher/e-flux landing | F24: Located - landing source | G24: Priority B pass: publisher and e-flux book landing found; full text may require purchase/library. | H24: Hui — Art and Cosmotechnics pdf DOI readable source | I24: https://www.google.com/search?q=Hui+%E2%80%94+Art+and+Cosmotechnics+pdf+DOI+readable+source | J24: 2026-08-13 | K24: Located (not charted) | L24: 1 | M24: WS-K | N24: B | O24: TELOS | P24: philosophical | Q24: philosophy of tech | R24: conceptual | S24: medium | T24: Art/landscape/symbol as resources to rethink technology beyond instrumentality. | U24: [to chart] | V24: [to chart] | W24: [to chart] | X24: no | Y24: yes | Z24: Justify ritual/symbolic/registration elements. | AA24: Aesthetic-symbolic relation as technical. | AB24: CF-7 | AC24: Ritual Transition Cards | AE24: Philosophical / historical / theoretical | AF24: 60 months | AG24: 2026-08-13 | AH24: 2031-08-13 | AI24: Current - re-search on schedule
A25: A1-04 | B25: Hui & Lemmens (eds.) — Cosmotechnics (Anthropocene) | C25: https://api.pageplace.de/preview/DT0400.9781000396324_A40918824/preview-9781000396324_A40918824.pdf | D25: https://www.routledge.com/Cosmotechnics-For-a-Renewed-Concept-of-Technology-in-the-Anthropocene/Hui-Lemmens/p/book/9780367769376 | E25: Preview PDF / publisher landing | F25: Located - preview source | G25: Priority B pass: preview/source landing found; full book likely library/purchase. | H25: Hui & Lemmens (eds.) — Cosmotechnics (Anthropocene) pdf DOI readable source | I25: https://www.google.com/search?q=Hui+%26+Lemmens+%28eds.%29+%E2%80%94+Cosmotechnics+%28Anthropocene%29+pdf+DOI+readable+source | J25: 2026-08-13 | K25: Located (not charted) | L25: 1 | M25: WS-K | N25: B | O25: TELOS | P25: review | Q25: philosophy of tech | R25: conceptual | S25: medium | T25: Technodiversity, pluralism, ecological stakes of technical practice. | U25: [to chart] | V25: [to chart] | W25: [to chart] | X25: no | Y25: yes | Z25: Pluralism at the scale of practice. | AA25: Ecological stakes of tools. | AB25: CF-8 | AC25: Cosmotechnic Audit Card | AE25: Empirical / applied research | AF25: 24 months | AG25: 2026-08-13 | AH25: 2028-08-13 | AI25: Current - re-search on schedule
A26: A1-05 | B26: Simondon — On the Mode of Existence of Technical Objects | C26: https://archive.org/details/onmodeofexistenc0000simo | D26: https://www.upress.umn.edu/9781937561031/on-the-mode-of-existence-of-technical-objects/ | E26: Archive lending / publisher landing | F26: Located - restricted readable | G26: Archive/publisher page located; use legal borrowed/purchased text for charting. | H26: Simondon — On the Mode of Existence of Technical Objects pdf DOI readable source | I26: https://www.google.com/search?q=Simondon+%E2%80%94+On+the+Mode+of+Existence+of+Technical+Objects+pdf+DOI+readable+source | J26: 2026-08-13 | K26: Located (not charted) | L26: 1 | M26: WS-K | N26: A | O26: TELOS/MECHANISM/DESIGN | P26: philosophical | Q26: philosophy of tech | R26: conceptual | S26: high | T26: Technical objects are evolving relational beings, not inert tools. | U26: [to chart] | V26: [to chart] | W26: [to chart] | X26: no | Y26: yes | Z26: Technical-object maturity; tool subordination. | AA26: Judge whether a tool integrates or alienates. | AB26: CF-5 | AC26: Cosmotechnic Audit Card | AE26: Philosophical / historical / theoretical | AF26: 60 months | AG26: 2026-08-13 | AH26: 2031-08-13 | AI26: Current - located, access/fit caveat
A27: A1-06 | B27: Simondon — Individuation (Form and Information) | C27: https://archive.org/details/individuationinl0000simo | D27: https://www.upress.umn.edu/9781937561048/individuation-in-light-of-notions-of-form-and-information/ | E27: Archive lending / publisher landing | F27: Located - restricted readable | G27: Archive/publisher page located for Simondon Individuation. | H27: Simondon — Individuation (Form and Information) pdf DOI readable source | I27: https://www.google.com/search?q=Simondon+%E2%80%94+Individuation+%28Form+and+Information%29+pdf+DOI+readable+source | J27: 2026-08-13 | K27: Located (not charted) | L27: 1 | M27: WS-K | N27: A | O27: TELOS/MECHANISM | P27: philosophical | Q27: philosophy of tech | R27: conceptual | S27: medium | T27: The person is an individuating system shaped through relations, not a fixed agent. | U27: [to chart] | V27: [to chart] | W27: [to chart] | X27: no | Y27: yes | Z27: Avoid rigid identity protocols. | AA27: Support becoming-through-practice. | AB27: CF-8 | AC27: Monstare Protocol vNext | AE27: Philosophical / historical / theoretical | AF27: 60 months | AG27: 2026-08-13 | AH27: 2031-08-13 | AI27: Current - located, access/fit caveat
A28: A1-07 | B28: Stiegler — Technics and Time v1 (Fault of Epimetheus) | C28: https://monoskop.org/images/6/6c/Stiegler_Bernard_Technics_and_Time_1_The_Fault_of_Epimetheus.pdf | D28: https://www.sup.org/books/title/?id=2213 | E28: Open PDF / publisher landing | F28: Located - readable source | G28: Readable PDF located; verify legality/preferred access during charting. | H28: Stiegler — Technics and Time v1 (Fault of Epimetheus) pdf DOI readable source | I28: https://www.google.com/search?q=Stiegler+%E2%80%94+Technics+and+Time+v1+%28Fault+of+Epimetheus%29+pdf+DOI+readable+source | J28: 2026-08-13 | K28: Located (not charted) | L28: 1 | M28: WS-K | N28: A | O28: TELOS/WARNING | P28: philosophical | Q28: philosophy of tech | R28: conceptual | S28: high | T28: Technics constitutes memory/inheritance; external memory is pharmakon (remedy+poison). | U28: [to chart] | V28: [to chart] | W28: [to chart] | X28: partial | Y28: yes | Z28: Frame external memory/AI as pharmacological. | AA28: Offloading has a poison dose. | AB28: CF-3 | AC28: AI Assistant Use Rules | AD28: OC-13 | AE28: Philosophical / historical / theoretical | AF28: 60 months | AG28: 2026-08-13 | AH28: 2031-08-13 | AI28: Current - re-search on schedule
A29: A1-08 | B29: Feenberg — Questioning Technology | C29: https://www.sfu.ca/~andrewf/Feenberg_Questioning_Technology.pdf | D29: https://www.routledge.com/Questioning-Technology/Feenberg/p/book/9780415197552 | E29: Open PDF / publisher landing | F29: Located - readable source | G29: Readable PDF located for Questioning Technology. | H29: Feenberg — Questioning Technology pdf DOI readable source | I29: https://www.google.com/search?q=Feenberg+%E2%80%94+Questioning+Technology+pdf+DOI+readable+source | J29: 2026-08-13 | K29: Located (not charted) | L29: 1 | M29: WS-K | N29: A | O29: CRITIQUE/DESIGN/TELOS | P29: philosophical | Q29: critical theory of tech | R29: conceptual | S29: high | T29: Technology is not neutral and can be democratized. | U29: [to chart] | V29: [to chart] | W29: [to chart] | X29: no | Y29: yes | Z29: User authorship beyond interface choice. | AA29: Design politics as moral stake. | AB29: CF-10 | AC29: Cosmotechnic Audit Card | AE29: Philosophical / historical / theoretical | AF29: 60 months | AG29: 2026-08-13 | AH29: 2031-08-13 | AI29: Current - re-search on schedule
A30: A1-09 | B30: Ihde — Technology and the Lifeworld | C30: https://archive.org/details/technologylifewo0000ihde | D30: https://iupress.org/9780253205605/technology-and-the-lifeworld/ | E30: Archive lending / publisher landing | F30: Located - restricted readable | G30: Archive lending and publisher page located. | H30: Ihde — Technology and the Lifeworld pdf DOI readable source | I30: https://www.google.com/search?q=Ihde+%E2%80%94+Technology+and+the+Lifeworld+pdf+DOI+readable+source | J30: 2026-08-13 | K30: Located (not charted) | L30: 1 | M30: WS-K | N30: A | O30: TELOS/MECHANISM | P30: philosophical | Q30: postphenomenology | R30: conceptual | S30: medium | T30: Technologies mediate perception and action (reveal/conceal/amplify/reduce). | U30: [to chart] | V30: [to chart] | W30: [to chart] | X30: no | Y30: yes | Z30: Ask what a tool reveals and hides. | AA30: Mediation as design question. | AB30: CF-5 | AC30: Cosmotechnic Audit Card | AE30: Philosophical / historical / theoretical | AF30: 60 months | AG30: 2026-08-13 | AH30: 2031-08-13 | AI30: Current - located, access/fit caveat
A31: A1-10 | B31: Verbeek — What Things Do | C31: https://archive.org/details/whatthingsdophil0000verb | D31: https://www.psupress.org/books/titles/0-271-02540-9.html | E31: Archive lending / publisher landing | F31: Located - restricted readable | G31: Archive lending and publisher page located. | H31: Verbeek — What Things Do pdf DOI readable source | I31: https://www.google.com/search?q=Verbeek+%E2%80%94+What+Things+Do+pdf+DOI+readable+source | J31: 2026-08-13 | K31: Located (not charted) | L31: 1 | M31: WS-L | N31: A | O31: DESIGN/TELOS/WARNING | P31: philosophical | Q31: postphenomenology | R31: conceptual | S31: high | T31: Technologies are moral mediators of action. | U31: [to chart] | V31: [to chart] | W31: [to chart] | X31: no | Y31: yes | Z31: Vocabulary for technological mediation of moral action. | AA31: Design as ethics-in-practice. | AB31: CF-4 | AC31: Cosmotechnic Audit Card | AE31: Philosophical / historical / theoretical | AF31: 60 months | AG31: 2026-08-13 | AH31: 2031-08-13 | AI31: Current - located, access/fit caveat
A32: A1-11 | B32: Winner — The Whale and the Reactor | C32: https://ratical.org/ratville/AoS/WhaleAndReactor.pdf | D32: https://press.uchicago.edu/ucp/books/book/chicago/W/bo5958056.html | E32: Open PDF / publisher landing | F32: Located - readable source | G32: Priority B pass: readable PDF located alongside Chicago publisher page. | H32: Winner — The Whale and the Reactor pdf DOI readable source | I32: https://www.google.com/search?q=Winner+%E2%80%94+The+Whale+and+the+Reactor+pdf+DOI+readable+source | J32: 2026-08-13 | K32: Located (not charted) | L32: 1 | M32: WS-L | N32: B | O32: WARNING/CRITIQUE | P32: philosophical | Q32: politics of tech | R32: conceptual | S32: medium | T32: Artifacts can embody politics. | U32: [to chart] | V32: [to chart] | W32: [to chart] | X32: no | Y32: yes | Z32: Ask whether an artifact enforces a moral/political order. | AA32: Artifacts are not neutral. | AB32: CF-10 | AC32: Design Veto Catalogue | AE32: Philosophical / historical / theoretical | AF32: 60 months | AG32: 2026-08-13 | AH32: 2031-08-13 | AI32: Current - re-search on schedule
A33: A1-12 | B33: Latour — Where Are the Missing Masses? | C33: https://www.bruno-latour.fr/node/258.html | D33: https://www.sfu.ca/~andrewf/Latour_MissingMasses.pdf | E33: Open HTML / PDF | F33: Located - readable source | G33: Priority B pass: author/official page and PDF located. | H33: Latour — Where Are the Missing Masses? pdf DOI readable source | I33: https://www.google.com/search?q=Latour+%E2%80%94+Where+Are+the+Missing+Masses%3F+pdf+DOI+readable+source | J33: 2026-08-13 | K33: Located (not charted) | L33: 1 | M33: WS-L | N33: B | O33: MECHANISM/DESIGN | P33: theoretical | Q33: STS | R33: conceptual | S33: medium | T33: Artifacts delegate, prescribe, and shape conduct. | U33: [to chart] | V33: [to chart] | W33: [to chart] | X33: no | Y33: partial | Z33: Task design as delegated morality. | AA33: Prescription is embedded in tools. | AB33: CF-4 | AC33: Monstare Protocol vNext | AE33: General supporting source | AF33: 36 months | AG33: 2026-08-13 | AH33: 2029-08-13 | AI33: Current - re-search on schedule
A34: A1-13 | B34: Borgmann — Technology and the Character of Contemporary Life | C34: https://archive.org/details/technologycharac0000borg | D34: https://press.uchicago.edu/ucp/books/book/chicago/T/bo3632495.html | E34: Archive lending / publisher landing | F34: Located - restricted readable | G34: Priority B pass: archive loan and publisher page located. | H34: Borgmann — Technology and the Character of Contemporary Life pdf DOI readable source | I34: https://www.google.com/search?q=Borgmann+%E2%80%94+Technology+and+the+Character+of+Contemporary+Life+pdf+DOI+readable+source | J34: 2026-08-13 | K34: Located (not charted) | L34: 1 | M34: WS-L | N34: B | O34: WARNING/TELOS | P34: philosophical | Q34: philosophy of tech | R34: conceptual | S34: medium | T34: Device paradigm hides focal practices behind commodities. | U34: [to chart] | V34: [to chart] | W34: [to chart] | X34: no | Y34: yes | Z34: Protect practice from convenience extraction. | AA34: Convenience can erase focal practice. | AB34: CF-5 | AC34: Anti-Extraction Audit | AE34: Philosophical / historical / theoretical | AF34: 60 months | AG34: 2026-08-13 | AH34: 2031-08-13 | AI34: Current - located, access/fit caveat
A35: A1-14 | B35: Mitcham — Thinking Through Technology | C35: https://archive.org/details/thinkingthrought0000mitc | D35: https://press.uchicago.edu/ucp/books/book/chicago/T/bo3625112.html | E35: Archive lending / publisher landing | F35: Located - restricted readable | G35: Priority B pass: archive loan and publisher page located. | H35: Mitcham — Thinking Through Technology pdf DOI readable source | I35: https://www.google.com/search?q=Mitcham+%E2%80%94+Thinking+Through+Technology+pdf+DOI+readable+source | J35: 2026-08-13 | K35: Located (not charted) | L35: 1 | M35: WS-K | N35: B | O35: TELOS/REVIEW | P35: review | Q35: philosophy of tech | R35: conceptual | S35: low | T35: Map of engineering vs humanities approaches to technology. | U35: [to chart] | V35: [to chart] | W35: [to chart] | X35: no | Y35: partial | Z35: Orient without overcommitting to one school. | AA35: Breadth over dogma. | AC35: Master Research Index | AE35: Empirical / applied research | AF35: 24 months | AG35: 2026-08-13 | AH35: 2028-08-13 | AI35: Current - located, access/fit caveat
A36: A1-15 | B36: Heidegger — The Question Concerning Technology | C36: https://monoskop.org/images/6/67/Heidegger_Martin_1962_1977_The_Question_Concerning_Technology.pdf | D36: https://monoskop.org/images/4/44/Heidegger_Martin_The_Question_Concerning_Technology_and_Other_Essays.pdf | E36: Open PDF copies / verify legal course-use copy | F36: Located - readable source | G36: Essay PDF and collected-volume PDF located; use legal/approved copy for charting. | H36: Heidegger — The Question Concerning Technology pdf DOI readable source | I36: https://www.google.com/search?q=Heidegger+%E2%80%94+The+Question+Concerning+Technology+pdf+DOI+readable+source | J36: 2026-08-13 | K36: Pending | L36: 1 | M36: WS-K | N36: C | O36: TELOS/CRITIQUE | P36: philosophical | Q36: philosophy of tech | R36: conceptual | S36: medium | T36: Enframing; technology as a mode of revealing. | U36: [to chart] | V36: [to chart] | W36: [to chart] | X36: no | Y36: yes | Z36: Pressure source, not governing authority (Hui responds to it). | AA36: Origin-point for the universality problem. | AB36: CF-8 | AC36: Cosmotechnic Audit Card | AE36: Philosophical / historical / theoretical | AF36: 60 months | AG36: 2026-08-13 | AH36: 2031-08-13 | AI36: Current - re-search on schedule
A37: A1-16 | B37: Mumford — Technics and Civilization | C37: https://archive.org/details/technicsciviliza0000lewi | D37: https://openlibrary.org/books/OL13718419M/Technics_and_civilization. | E37: Archive lending / Open Library landing | F37: Located - restricted readable | G37: Controlled digital lending and catalog path located for Technics and Civilization. | H37: Mumford — Technics and Civilization pdf DOI readable source | I37: https://www.google.com/search?q=Mumford+%E2%80%94+Technics+and+Civilization+pdf+DOI+readable+source | J37: 2026-08-13 | K37: Pending | L37: 1 | M37: WS-K | N37: C | O37: TELOS/CONTEXT | P37: theoretical | Q37: history of tech | R37: conceptual | S37: low | T37: Long history of technics and social form. | U37: [to chart] | V37: [to chart] | W37: [to chart] | X37: no | Y37: partial | Z37: Context only. | AA37: Historical breadth. | AC37: Master Research Index | AE37: General supporting source | AF37: 36 months | AG37: 2026-08-13 | AH37: 2029-08-13 | AI37: Current - located, access/fit caveat
A38: A1-17 | B38: Ellul — The Technological Society | C38: https://archive.org/details/technologicalsoc0000ellu | D38: https://archive.org/details/JacquesEllulTheTechnologicalSociety | E38: Archive lending / alternate archive scan | F38: Located - restricted readable | G38: Archive access path located; use legal borrowed/library copy for full charting. | H38: Ellul — The Technological Society pdf DOI readable source | I38: https://www.google.com/search?q=Ellul+%E2%80%94+The+Technological+Society+pdf+DOI+readable+source | J38: 2026-08-13 | K38: Pending | L38: 1 | M38: WS-K | N38: C | O38: WARNING | P38: theoretical | Q38: philosophy of tech | R38: conceptual | S38: medium | T38: Technique as autonomous, self-augmenting order. | U38: [to chart] | V38: [to chart] | W38: [to chart] | X38: no | Y38: yes | Z38: Warning about technical autonomy. | AA38: Technique can govern the human. | AB38: CF-4 | AC38: Design Veto Catalogue | AE38: Philosophical / historical / theoretical | AF38: 60 months | AG38: 2026-08-13 | AH38: 2031-08-13 | AI38: Current - located, access/fit caveat
A39: A1-18 | B39: Haraway — A Cyborg Manifesto | C39: https://www.sfu.ca/~decaste/OISE/page2/files/HarawayCyborg.pdf | D39: https://archive.org/details/anarchy_Cyborg_Manifesto_Harroway | E39: Open PDF / archive landing | F39: Located - readable source | G39: Readable PDF and archive landing located; verify preferred edition during charting. | H39: Haraway — A Cyborg Manifesto pdf DOI readable source | I39: https://www.google.com/search?q=Haraway+%E2%80%94+A+Cyborg+Manifesto+pdf+DOI+readable+source | J39: 2026-08-13 | K39: Pending | L39: 1 | M39: WS-L | N39: C | O39: CRITIQUE | P39: theoretical | Q39: STS/feminist | R39: conceptual | S39: low | T39: Hybrid human-machine boundaries; refusal of purity. | U39: [to chart] | V39: [to chart] | W39: [to chart] | X39: no | Y39: partial | Z39: Contextual reframing. | AA39: Boundary plurality. | AC39: Technodiversity & Cultural Fit Sheet | AE39: General supporting source | AF39: 36 months | AG39: 2026-08-13 | AH39: 2029-08-13 | AI39: Current - re-search on schedule
A40: A1-19 | B40: Verbeek — Moralizing Technology | C40: https://archive.org/details/moralizingtechno0000verb | D40: https://press.uchicago.edu/ucp/books/book/chicago/M/bo11309162.html | E40: Archive lending / publisher landing | F40: Located - restricted readable | G40: Archive lending and University of Chicago Press landing located. | H40: Verbeek — Moralizing Technology pdf DOI readable source | I40: https://www.google.com/search?q=Verbeek+%E2%80%94+Moralizing+Technology+pdf+DOI+readable+source | J40: 2026-08-13 | K40: Pending | L40: 1 | M40: WS-L | N40: C | O40: DESIGN/TELOS | P40: philosophical | Q40: postphenomenology | R40: conceptual | S40: medium | T40: Designers materialize morality; ethics of things. | U40: [to chart] | V40: [to chart] | W40: [to chart] | X40: no | Y40: yes | Z40: Deliberate moral mediation in design. | AA40: Morality can be built in. | AB40: CF-4 | AC40: Cosmotechnic Audit Card | AE40: Philosophical / historical / theoretical | AF40: 60 months | AG40: 2026-08-13 | AH40: 2031-08-13 | AI40: Current - located, access/fit caveat
...

Sheet Source Patch Log
A1: Patch Date | B1: Patch Type | C1: Rows Updated | D1: Columns Added | E1: Rows Removed | F1: Existing Source Cells Removed | G1: Notes
A2: 2026-08-13 | B2: Additive patch | C2: 38 | D2: Staleness Domain, Re-search Interval, Last Verified Date, Re-search By, Staleness Status | E2: 0 | F2: 0 | G2: Patched staleness columns at workbook end and completed source-location pass for all previously queued/missing rows. Existing source links were preserved; only queued rows were filled.
A3: 2026-08-13 | B3: Source rows completed | C3: A1-15, A1-16, A1-17, A1-18, A1-19, A3-07, A3-08, A3-09, A3-10, A4-07, A4-08, A4-09, A4-10, A5-07, A5-08, A5-09, A5-10, A6-07, A6-08, A6-09, A6-10, A7-07, A7-08, A7-09, A7-10, A8-07, A8-08, A8-09, A8-10, A9-07, A9-08, A9-09, A9-10, A9-11, A10-05, A10-06, A10-07, A10-08 | G3: Rows were source-located, not evidentially charted. Citation is still not evidence.
